<?xml version="1.0" ?>
<!-- =================================================================================== -->
<!-- |    This document was autogenerated by xacro from robot.xacro                    | -->
<!-- |    EDITING THIS FILE BY HAND IS NOT RECOMMENDED                                 | -->
<!-- =================================================================================== -->
<robot name="URDF">
  <material name="silver">
    <color rgba="0.700 0.700 0.700 1.000"/>
  </material>
  <transmission name="Revolute 1_tran">
    <type>transmission_interface/SimpleTransmission</type>
    <joint name="Revolute 1">
      <hardwareInterface>hardware_interface/EffortJointInterface</hardwareInterface>
    </joint>
    <actuator name="Revolute 1_actr">
      <hardwareInterface>hardware_interface/EffortJointInterface</hardwareInterface>
      <mechanicalReduction>1</mechanicalReduction>
    </actuator>
  </transmission>
  <transmission name="Revolute 2_tran">
    <type>transmission_interface/SimpleTransmission</type>
    <joint name="Revolute 2">
      <hardwareInterface>hardware_interface/EffortJointInterface</hardwareInterface>
    </joint>
    <actuator name="Revolute 2_actr">
      <hardwareInterface>hardware_interface/EffortJointInterface</hardwareInterface>
      <mechanicalReduction>1</mechanicalReduction>
    </actuator>
  </transmission>
  <transmission name="Revolute 3_tran">
    <type>transmission_interface/SimpleTransmission</type>
    <joint name="Revolute 3">
      <hardwareInterface>hardware_interface/EffortJointInterface</hardwareInterface>
    </joint>
    <actuator name="Revolute 3_actr">
      <hardwareInterface>hardware_interface/EffortJointInterface</hardwareInterface>
      <mechanicalReduction>1</mechanicalReduction>
    </actuator>
  </transmission>
  <transmission name="Revolute 4_tran">
    <type>transmission_interface/SimpleTransmission</type>
    <joint name="Revolute 4">
      <hardwareInterface>hardware_interface/EffortJointInterface</hardwareInterface>
    </joint>
    <actuator name="Revolute 4_actr">
      <hardwareInterface>hardware_interface/EffortJointInterface</hardwareInterface>
      <mechanicalReduction>1</mechanicalReduction>
    </actuator>
  </transmission>
  <transmission name="Revolute 5_tran">
    <type>transmission_interface/SimpleTransmission</type>
    <joint name="Revolute 5">
      <hardwareInterface>hardware_interface/EffortJointInterface</hardwareInterface>
    </joint>
    <actuator name="Revolute 5_actr">
      <hardwareInterface>hardware_interface/EffortJointInterface</hardwareInterface>
      <mechanicalReduction>1</mechanicalReduction>
    </actuator>
  </transmission>
  <transmission name="Revolute 6_tran">
    <type>transmission_interface/SimpleTransmission</type>
    <joint name="Revolute 6">
      <hardwareInterface>hardware_interface/EffortJointInterface</hardwareInterface>
    </joint>
    <actuator name="Revolute 6_actr">
      <hardwareInterface>hardware_interface/EffortJointInterface</hardwareInterface>
      <mechanicalReduction>1</mechanicalReduction>
    </actuator>
  </transmission>
  <gazebo>
    <plugin filename="libgazebo_ros_control.so" name="control"/>
  </gazebo>
  <gazebo reference="base_link">
    <material>Gazebo/Silver</material>
    <mu1>0.2</mu1>
    <mu2>0.2</mu2>
    <selfCollide>true</selfCollide>
    <gravity>true</gravity>
  </gazebo>
  <gazebo reference="Link_0_1">
    <material>Gazebo/Silver</material>
    <mu1>0.2</mu1>
    <mu2>0.2</mu2>
    <selfCollide>true</selfCollide>
  </gazebo>
  <gazebo reference="Link_1_1">
    <material>Gazebo/Silver</material>
    <mu1>0.2</mu1>
    <mu2>0.2</mu2>
    <selfCollide>true</selfCollide>
  </gazebo>
  <gazebo reference="Link_2_1">
    <material>Gazebo/Silver</material>
    <mu1>0.2</mu1>
    <mu2>0.2</mu2>
    <selfCollide>true</selfCollide>
  </gazebo>
  <gazebo reference="Link_3_1">
    <material>Gazebo/Silver</material>
    <mu1>0.2</mu1>
    <mu2>0.2</mu2>
    <selfCollide>true</selfCollide>
  </gazebo>
  <gazebo reference="Link_4_1">
    <material>Gazebo/Silver</material>
    <mu1>0.2</mu1>
    <mu2>0.2</mu2>
    <selfCollide>true</selfCollide>
  </gazebo>
  <gazebo reference="Link_5_1">
    <material>Gazebo/Silver</material>
    <mu1>0.2</mu1>
    <mu2>0.2</mu2>
    <selfCollide>true</selfCollide>
  </gazebo>
  <!-- Root link with inertia (kept for dynamic purposes) -->
  <link name="base_link">
    <inertial>
      <origin rpy="0 0 0" xyz="5.500306683749839e-09 1.7690045296987684e-08 -0.04351821247312735"/>
      <mass value="9.665954367017239"/>
      <inertia ixx="0.029174" ixy="0.0" ixz="0.0" iyy="0.029174" iyz="0.0" izz="0.044786"/>
    </inertial>
    <visual>
      <origin rpy="0 0 0" xyz="0 0 0"/>
      <geometry>
        <mesh filename="package://arm-planner/meshes/base_link.stl" scale="0.001 0.001 0.001"/>
      </geometry>
      <material name="silver"/>
    </visual>
    <collision>
      <origin rpy="0 0 0" xyz="0 0 0"/>
      <geometry>
        <mesh filename="package://arm-planner/meshes/base_link.stl" scale="0.001 0.001 0.001"/>
      </geometry>
    </collision>
  </link>
  <!-- Dummy link to serve as new base for KDL -->
  <link name="dummy_base"/>
  <!-- Fixed joint between base_link and dummy_base (no need for joint states) -->
  <joint name="base_to_dummy" type="fixed">
    <origin rpy="0 0 0" xyz="0 0 0"/>
    <parent link="base_link"/>
    <child link="dummy_base"/>
  </joint>
  <!-- JOINT 1: Was "Revolute 1", now "joint1" -->
  <joint name="joint1" type="revolute">
    <origin rpy="0 0 0" xyz="0.0 0.0 0.01"/>
    <parent link="dummy_base"/>
    <child link="Link_0_1"/>
    <axis xyz="0.0 0.0 1.0"/>
    <limit effort="100" lower="-3.141593" upper="3.141593" velocity="100"/>
  </joint>
  <link name="Link_0_1">
    <inertial>
      <origin rpy="0 0 0" xyz="0.025147305768597313 3.714411619225575e-05 0.06827470074076418"/>
      <mass value="9.512665721240847"/>
      <inertia ixx="0.030352" ixy="9e-06" ixz="-0.004461" iyy="0.037217" iyz="-1.6e-05" izz="0.039916"/>
    </inertial>
    <visual>
      <origin rpy="0 0 0" xyz="0 0 -0.01"/>
      <geometry>
        <mesh filename="package://arm-planner/meshes/Link_0_1.stl" scale="0.001 0.001 0.001"/>
      </geometry>
      <material name="silver"/>
    </visual>
    <collision>
      <origin rpy="0 0 0" xyz="0 0 -0.01"/>
      <geometry>
        <mesh filename="package://arm-planner/meshes/Link_0_1.stl" scale="0.001 0.001 0.001"/>
      </geometry>
    </collision>
  </link>
  <!-- JOINT 2: Was "Revolute 2", now "joint2" -->
  <joint name="joint2" type="revolute">
    <origin rpy="0 0 0" xyz="0.0898 -0.0 0.085"/>
    <parent link="Link_0_1"/>
    <child link="Link_1_1"/>
    <axis xyz="-1.0 0.0 0.0"/>
    <limit effort="100" lower="-1.570796" upper="1.570796" velocity="100"/>
  </joint>
  <link name="Link_1_1">
    <inertial>
      <origin rpy="0 0 0" xyz="0.05116110784738716 -1.276329509484605e-09 0.17500000003731517"/>
      <mass value="25.335856608089017"/>
      <inertia ixx="0.54402" ixy="0.0" ixz="0.0003" iyy="0.534675" iyz="0.000331" izz="0.07227"/>
    </inertial>
    <visual>
      <origin rpy="0 0 0" xyz="-0.0898 0 -0.095"/>
      <geometry>
        <mesh filename="package://arm-planner/meshes/Link_1_1.stl" scale="0.001 0.001 0.001"/>
      </geometry>
      <material name="silver"/>
    </visual>
    <collision>
      <origin rpy="0 0 0" xyz="-0.0898 0 -0.095"/>
      <geometry>
        <mesh filename="package://arm-planner/meshes/Link_1_1.stl" scale="0.001 0.001 0.001"/>
      </geometry>
    </collision>
  </link>
  <!-- JOINT 3: Was "Revolute 3", now "joint3" -->
  <joint name="joint3" type="revolute">
    <origin rpy="0 0 0" xyz="0.0 0.0 0.35"/>
    <parent link="Link_1_1"/>
    <child link="Link_2_1"/>
    <axis xyz="-1.0 0.0 0.0"/>
    <limit effort="100" lower="-3.141593" upper="1.047198" velocity="100"/>
  </joint>
  <link name="Link_2_1">
    <inertial>
      <origin rpy="0 0 0" xyz="-0.07858780325051475 0.07482766866821508 -0.00012906577646332185"/>
      <mass value="27.641428291972183"/>
      <inertia ixx="0.291742" ixy="0.015471" ixz="6.9e-05" iyy="0.075237" iyz="0.000231" izz="0.302588"/>
    </inertial>
    <visual>
      <origin rpy="0 0 0" xyz="-0.0898 -0.0 -0.445"/>
      <geometry>
        <mesh filename="package://arm-planner/meshes/Link_2_1.stl" scale="0.001 0.001 0.001"/>
      </geometry>
      <material name="silver"/>
    </visual>
    <collision>
      <origin rpy="0 0 0" xyz="-0.0898 -0.0 -0.445"/>
      <geometry>
        <mesh filename="package://arm-planner/meshes/Link_2_1.stl" scale="0.001 0.001 0.001"/>
      </geometry>
    </collision>
  </link>
  <!-- JOINT 4: Was "Revolute 4", now "joint4" -->
  <joint name="joint4" type="revolute">
    <origin rpy="0 0 0" xyz="-0.0148 0.255 0.0"/>
    <parent link="Link_2_1"/>
    <child link="Link_3_1"/>
    <axis xyz="1.0 0.0 0.0"/>
    <limit effort="100" lower="-4.014257" upper="0.785398" velocity="100"/>
  </joint>
  <link name="Link_3_1">
    <inertial>
      <origin rpy="0 0 0" xyz="0.05280646080955524 -0.00014958827631367244 0.014397391676137572"/>
      <mass value="5.7113026691342785"/>
      <inertia ixx="0.012888" ixy="1.2e-05" ixz="-0.001515" iyy="0.015126" iyz="7.1e-05" izz="0.014242"/>
    </inertial>
    <visual>
      <origin rpy="0 0 0" xyz="-0.075 -0.255 -0.445"/>
      <geometry>
        <mesh filename="package://arm-planner/meshes/Link_3_1.stl" scale="0.001 0.001 0.001"/>
      </geometry>
      <material name="silver"/>
    </visual>
    <collision>
      <origin rpy="0 0 0" xyz="-0.075 -0.255 -0.445"/>
      <geometry>
        <mesh filename="package://arm-planner/meshes/Link_3_1.stl" scale="0.001 0.001 0.001"/>
      </geometry>
    </collision>
  </link>
  <!-- JOINT 5: Was "Revolute 5", now "joint5" -->
  <joint name="joint5" type="revolute">
    <origin rpy="0 0 0" xyz="0.07 0.0 0.08"/>
    <parent link="Link_3_1"/>
    <child link="Link_4_1"/>
    <axis xyz="0.0 0.0 1.0"/>
    <limit effort="100" lower="-3.141593" upper="3.141593" velocity="100"/>
  </joint>
  <link name="Link_4_1">
    <inertial>
      <origin rpy="0 0 0" xyz="2.348099192109321e-05 0.004226979419264587 0.04977103581625053"/>
      <mass value="4.854306730672969"/>
      <inertia ixx="0.010705" ixy="3e-06" ixz="-5e-06" iyy="0.012385" iyz="-0.000517" izz="0.008722"/>
    </inertial>
    <visual>
      <origin rpy="0 0 0" xyz="-0.145 -0.255 -0.525"/>
      <geometry>
        <mesh filename="package://arm-planner/meshes/Link_4_1.stl" scale="0.001 0.001 0.001"/>
      </geometry>
      <material name="silver"/>
    </visual>
    <collision>
      <origin rpy="0 0 0" xyz="-0.145 -0.255 -0.525"/>
      <geometry>
        <mesh filename="package://arm-planner/meshes/Link_4_1.stl" scale="0.001 0.001 0.001"/>
      </geometry>
    </collision>
  </link>
  <!-- JOINT 6: Was "Revolute 6", now "joint6" (type continuous is fine) -->
  <joint name="joint6" type="continuous">
    <origin rpy="0 0 0" xyz="0.0 0.0645 0.07"/>
    <parent link="Link_4_1"/>
    <child link="Link_5_1"/>
    <axis xyz="0.0 -1.0 0.0"/>
  </joint>
  <link name="Link_5_1">
    <inertial>
      <origin rpy="0 0 0" xyz="2.1371793224034263e-15 0.017187500000006017 -3.774758283725532e-14"/>
      <mass value="0.5137812985573593"/>
      <inertia ixx="0.000129" ixy="0.0" ixz="0.0" iyy="0.000145" iyz="0.0" izz="0.000129"/>
    </inertial>
    <visual>
      <origin rpy="0 0 0" xyz="-0.145 -0.3195 -0.595"/>
      <geometry>
        <mesh filename="package://arm-planner/meshes/Link_5_1.stl" scale="0.001 0.001 0.001"/>
      </geometry>
      <material name="silver"/>
    </visual>
    <collision>
      <origin rpy="0 0 0" xyz="-0.145 -0.3195 -0.595"/>
      <geometry>
        <mesh filename="package://arm-planner/meshes/Link_5_1.stl" scale="0.001 0.001 0.001"/>
      </geometry>
    </collision>
  </link>
</robot>
